<?xml version="1.0" encoding="utf-8"?>
<mujoco>
	<worldbody>
		<body name="box" pos="0.15 0.15 0.15">
			<joint axis="1 0 0" damping="0.1" name="tx" pos="0 0 0" type="slide"></joint>
			<joint axis="0 1 0" damping="0.1" name="ty" pos="0 0 0" type="slide"></joint>
			<joint axis="0 0 1" damping="10000" name="tz" pos="0 0 0" type="slide"></joint>
			<geom name="box" mass="1" pos="0 0 0" rgba="0 1 0 1" type="box" euler="1.57 0 0"></geom>
		</body>
		<body name="annotation:outer_bound" pos="0 0 0">
			<geom conaffinity="0" contype="0" mass="0" pos="0 0 0" rgba="0.417 0.7203 0.0001 0.1" size="0.15" type="box"></geom>
		</body>
	</worldbody>
</mujoco>