<?xml version="1.0" encoding="utf-8"?>
<mujoco>
	<compiler angle="radian" coordinate="local" meshdir="/Users/tom/dev/imperial/FYP/MAax/assets/stls" texturedir="/Users/tom/dev/imperial/FYP/MAax/assets/textures"></compiler>
	<option timestep="0.005">
		<flag warmstart="enable"></flag>
	</option>
	<worldbody>
		<geom name="floor0" pos="3 3 0" size="3 3 1" type="plane" condim="3"></geom>
		<body name="floor0" pos="3 3 0"></body>
		<body pos="0.15 0.15 0.15" name="agent0_agent0">
			<joint axis="1 0 0" damping="0.1" name="agent0_tx" pos="0 0 0" type="slide"></joint>
			<joint axis="0 1 0" damping="0.1" name="agent0_ty" pos="0 0 0" type="slide"></joint>
			<joint axis="0 0 1" damping="1" name="agent0_tz" pos="0 0 0" type="slide"></joint>
			<geom name="agent0_agent" mass="1" pos="0 0 0" rgba="0.258824 0.921569 0.956863 1" size="0.15" type="sphere" euler="1.57 0 0" friction="0.01"></geom>
		</body>
		<body pos="0.15 0.15 0.15" name="agent1_agent1">
			<joint axis="1 0 0" damping="0.1" name="agent1_tx" pos="0 0 0" type="slide"></joint>
			<joint axis="0 1 0" damping="0.1" name="agent1_ty" pos="0 0 0" type="slide"></joint>
			<joint axis="0 0 1" damping="1" name="agent1_tz" pos="0 0 0" type="slide"></joint>
			<geom name="agent1_agent" mass="1" pos="0 0 0" rgba="0.258824 0.921569 0.956863 1" size="0.15" type="sphere" euler="1.57 0 0" friction="0.01"></geom>
		</body>
		<body name="moveable_box0" pos="0.25 0.25 0.25">
			<joint name="moveable_box0:slide0" axis="1 0 0" type="slide" damping="0.01" pos="0 0 0"></joint>
			<joint name="moveable_box0:slide1" axis="0 1 0" type="slide" damping="0.01" pos="0 0 0"></joint>
			<joint name="moveable_box0:slide2" axis="0 0 1" type="slide" damping="0.01" pos="0 0 0"></joint>
			<geom size="0.25 0.25 0.25" type="box" condim="3" name="moveable_box0" material="material0" mass="1" friction="0.2"></geom>
		</body>
		<body name="moveable_box1" pos="0.25 0.25 0.25">
			<joint name="moveable_box1:slide0" axis="1 0 0" type="slide" damping="0.01" pos="0 0 0"></joint>
			<joint name="moveable_box1:slide1" axis="0 1 0" type="slide" damping="0.01" pos="0 0 0"></joint>
			<joint name="moveable_box1:slide2" axis="0 0 1" type="slide" damping="0.01" pos="0 0 0"></joint>
			<geom size="0.25 0.25 0.25" type="box" condim="3" name="moveable_box1" material="material1" mass="1" friction="0.2"></geom>
		</body>
		<body pos="0.25 0.25 0.25" name="ramp0_ramp0">
			<geom name="ramp0_ramp" pos="0 0 0" type="mesh" mesh="ramp0_ramp" mass="1" material="material2" friction="0.01"></geom>
			<joint type="free" name="ramp0_free" damping="0.001"></joint>
		</body>
		<body pos="0.25 0.25 0.25" name="ramp1_ramp1">
			<geom name="ramp1_ramp" pos="0 0 0" type="mesh" mesh="ramp1_ramp" mass="1" material="material3" friction="0.01"></geom>
			<joint type="free" name="ramp1_free" damping="0.001"></joint>
		</body>
		<body pos="0.25 0.25 0.25" name="ramp2_ramp2">
			<geom name="ramp2_ramp" pos="0 0 0" type="mesh" mesh="ramp2_ramp" mass="1" material="material4" friction="0.01"></geom>
			<joint type="free" name="ramp2_free" damping="0.001"></joint>
		</body>
		<body pos="0.25 0.25 0.25" name="ramp3_ramp3">
			<geom name="ramp3_ramp" pos="0 0 0" type="mesh" mesh="ramp3_ramp" mass="1" material="material5" friction="0.01"></geom>
			<joint type="free" name="ramp3_free" damping="0.001"></joint>
		</body>
		<body pos="0.25 0.25 0.25" name="ramp4_ramp4">
			<geom name="ramp4_ramp" pos="0 0 0" type="mesh" mesh="ramp4_ramp" mass="1" material="material6" friction="0.01"></geom>
			<joint type="free" name="ramp4_free" damping="0.001"></joint>
		</body>
		<body pos="0.25 0.25 0.25" name="ramp5_ramp5">
			<geom name="ramp5_ramp" pos="0 0 0" type="mesh" mesh="ramp5_ramp" mass="1" material="material7" friction="0.01"></geom>
			<joint type="free" name="ramp5_free" damping="0.001"></joint>
		</body>
	</worldbody>
	<actuator>
		<motor gear="100" joint="agent0_tx"></motor>
		<motor gear="100" joint="agent0_ty"></motor>
		<motor gear="100" joint="agent1_tx"></motor>
		<motor gear="100" joint="agent1_ty"></motor>
	</actuator>
	<asset>
		<texture name="texture_material0" type="cube" builtin="none" file="chars/A.png" gridlayout=".U..LFRB.D.." gridsize="3 4"></texture>
		<texture name="texture_material1" type="cube" builtin="none" file="chars/B.png" gridlayout=".U..LFRB.D.." gridsize="3 4"></texture>
		<texture name="texture_material2" type="cube" builtin="none" file="chars/A.png" gridlayout=".U..LFRB.D.." gridsize="3 4"></texture>
		<texture name="texture_material3" type="cube" builtin="none" file="chars/B.png" gridlayout=".U..LFRB.D.." gridsize="3 4"></texture>
		<texture name="texture_material4" type="cube" builtin="none" file="chars/C.png" gridlayout=".U..LFRB.D.." gridsize="3 4"></texture>
		<texture name="texture_material5" type="cube" builtin="none" file="chars/D.png" gridlayout=".U..LFRB.D.." gridsize="3 4"></texture>
		<texture name="texture_material6" type="cube" builtin="none" file="chars/E.png" gridlayout=".U..LFRB.D.." gridsize="3 4"></texture>
		<texture name="texture_material7" type="cube" builtin="none" file="chars/F.png" gridlayout=".U..LFRB.D.." gridsize="3 4"></texture>
		<material name="material0" texture="texture_material0"></material>
		<material name="material1" texture="texture_material1"></material>
		<material name="ramp0_rampmat" specular="1" shininess="0.3" reflectance="0" rgba="0 0.5 1 1"></material>
		<material name="material2" texture="texture_material2"></material>
		<material name="ramp1_rampmat" specular="1" shininess="0.3" reflectance="0" rgba="0 0.5 1 1"></material>
		<material name="material3" texture="texture_material3"></material>
		<material name="ramp2_rampmat" specular="1" shininess="0.3" reflectance="0" rgba="0 0.5 1 1"></material>
		<material name="material4" texture="texture_material4"></material>
		<material name="ramp3_rampmat" specular="1" shininess="0.3" reflectance="0" rgba="0 0.5 1 1"></material>
		<material name="material5" texture="texture_material5"></material>
		<material name="ramp4_rampmat" specular="1" shininess="0.3" reflectance="0" rgba="0 0.5 1 1"></material>
		<material name="material6" texture="texture_material6"></material>
		<material name="ramp5_rampmat" specular="1" shininess="0.3" reflectance="0" rgba="0 0.5 1 1"></material>
		<material name="material7" texture="texture_material7"></material>
		<mesh file="ramp.stl" name="ramp0_ramp" scale="0.5 0.5 0.5"></mesh>
		<mesh file="ramp.stl" name="ramp1_ramp" scale="0.5 0.5 0.5"></mesh>
		<mesh file="ramp.stl" name="ramp2_ramp" scale="0.5 0.5 0.5"></mesh>
		<mesh file="ramp.stl" name="ramp3_ramp" scale="0.5 0.5 0.5"></mesh>
		<mesh file="ramp.stl" name="ramp4_ramp" scale="0.5 0.5 0.5"></mesh>
		<mesh file="ramp.stl" name="ramp5_ramp" scale="0.5 0.5 0.5"></mesh>
	</asset>
</mujoco>