<?xml version="1.0" encoding="utf-8"?>
<mujoco>
	<compiler angle="radian" coordinate="local" meshdir="/rds/general/user/tla19/home/FYP/MAax/assets/stls" texturedir="/rds/general/user/tla19/home/FYP/MAax/assets/textures"></compiler>
	<option timestep="0.005">
		<flag warmstart="enable"></flag>
	</option>
	<worldbody>
		<geom name="floor0" pos="3 3 0" size="3 3 1" type="plane" condim="3"></geom>
		<body name="floor0" pos="3 3 0"></body>
		<body pos="0.15 0.15 0.15" name="agent0_agent0">
			<joint axis="1 0 0" damping="0.01" name="agent0_slide0" pos="0 0 0" type="slide"></joint>
			<joint axis="0 1 0" damping="0.01" name="agent0_slide1" pos="0 0 0" type="slide"></joint>
			<joint axis="0 0 1" damping="0.01" name="agent0_hinge0" pos="0 0 0" type="hinge"></joint>
			<geom name="agent0_agent" mass="1" pos="0 0 0" rgba="0.258824 0.921569 0.956863 1" size="0.15" type="sphere" euler="1.57 0 0" friction="0.01"></geom>
		</body>
		<body pos="0.15 0.15 0.15" name="agent1_agent1">
			<joint axis="1 0 0" damping="0.01" name="agent1_slide0" pos="0 0 0" type="slide"></joint>
			<joint axis="0 1 0" damping="0.01" name="agent1_slide1" pos="0 0 0" type="slide"></joint>
			<joint axis="0 0 1" damping="0.01" name="agent1_hinge0" pos="0 0 0" type="hinge"></joint>
			<geom name="agent1_agent" mass="1" pos="0 0 0" rgba="0.258824 0.921569 0.956863 1" size="0.15" type="sphere" euler="1.57 0 0" friction="0.01"></geom>
		</body>
		<body pos="0.15 0.15 0.15" name="agent2_agent2">
			<joint axis="1 0 0" damping="0.01" name="agent2_slide0" pos="0 0 0" type="slide"></joint>
			<joint axis="0 1 0" damping="0.01" name="agent2_slide1" pos="0 0 0" type="slide"></joint>
			<joint axis="0 0 1" damping="0.01" name="agent2_hinge0" pos="0 0 0" type="hinge"></joint>
			<geom name="agent2_agent" mass="1" pos="0 0 0" rgba="0.258824 0.921569 0.956863 1" size="0.15" type="sphere" euler="1.57 0 0" friction="0.01"></geom>
		</body>
		<body pos="0.15 0.15 0.15" name="agent3_agent3">
			<joint axis="1 0 0" damping="0.01" name="agent3_slide0" pos="0 0 0" type="slide"></joint>
			<joint axis="0 1 0" damping="0.01" name="agent3_slide1" pos="0 0 0" type="slide"></joint>
			<joint axis="0 0 1" damping="0.01" name="agent3_hinge0" pos="0 0 0" type="hinge"></joint>
			<geom name="agent3_agent" mass="1" pos="0 0 0" rgba="0.258824 0.921569 0.956863 1" size="0.15" type="sphere" euler="1.57 0 0" friction="0.01"></geom>
		</body>
		<body name="moveable-box0" pos="0.25 0.25 0.25">
			<joint type="free" name="moveable-box0_free" damping="0.01" pos="0 0 0"></joint>
			<geom size="0.25 0.25 0.25" type="box" condim="3" name="moveable-box0" rgba="1 0.5 0.8 1" mass="1" friction="0.2"></geom>
		</body>
		<body name="moveable-box1" pos="0.25 0.25 0.25">
			<joint type="free" name="moveable-box1_free" damping="0.01" pos="0 0 0"></joint>
			<geom size="0.25 0.25 0.25" type="box" condim="3" name="moveable-box1" rgba="1 0.5 0.8 1" mass="1" friction="0.2"></geom>
		</body>
		<body name="moveable-box2" pos="0.25 0.25 0.25">
			<joint type="free" name="moveable-box2_free" damping="0.01" pos="0 0 0"></joint>
			<geom size="0.25 0.25 0.25" type="box" condim="3" name="moveable-box2" rgba="1 0.5 0.8 1" mass="1" friction="0.2"></geom>
		</body>
		<body name="moveable-box3" pos="0.25 0.25 0.25">
			<joint type="free" name="moveable-box3_free" damping="0.01" pos="0 0 0"></joint>
			<geom size="0.25 0.25 0.25" type="box" condim="3" name="moveable-box3" rgba="1 0.5 0.8 1" mass="1" friction="0.2"></geom>
		</body>
		<body name="moveable-box4" pos="0.25 0.25 0.25">
			<joint type="free" name="moveable-box4_free" damping="0.01" pos="0 0 0"></joint>
			<geom size="0.25 0.25 0.25" type="box" condim="3" name="moveable-box4" rgba="1 0.5 0.8 1" mass="1" friction="0.2"></geom>
		</body>
		<body name="moveable-box5" pos="0.25 0.25 0.25">
			<joint type="free" name="moveable-box5_free" damping="0.01" pos="0 0 0"></joint>
			<geom size="0.25 0.25 0.25" type="box" condim="3" name="moveable-box5" rgba="1 0.5 0.8 1" mass="1" friction="0.2"></geom>
		</body>
		<body name="moveable-box6" pos="0.25 0.25 0.25">
			<joint type="free" name="moveable-box6_free" damping="0.01" pos="0 0 0"></joint>
			<geom size="0.25 0.25 0.25" type="box" condim="3" name="moveable-box6" rgba="1 0.5 0.8 1" mass="1" friction="0.2"></geom>
		</body>
		<body name="moveable-box7" pos="0.25 0.25 0.25">
			<joint type="free" name="moveable-box7_free" damping="0.01" pos="0 0 0"></joint>
			<geom size="0.25 0.25 0.25" type="box" condim="3" name="moveable-box7" rgba="1 0.5 0.8 1" mass="1" friction="0.2"></geom>
		</body>
		<body name="moveable-box8" pos="0.25 0.25 0.25">
			<joint type="free" name="moveable-box8_free" damping="0.01" pos="0 0 0"></joint>
			<geom size="0.25 0.25 0.25" type="box" condim="3" name="moveable-box8" rgba="1 0.5 0.8 1" mass="1" friction="0.2"></geom>
		</body>
		<body name="moveable-box9" pos="0.25 0.25 0.25">
			<joint type="free" name="moveable-box9_free" damping="0.01" pos="0 0 0"></joint>
			<geom size="0.25 0.25 0.25" type="box" condim="3" name="moveable-box9" rgba="1 0.5 0.8 1" mass="1" friction="0.2"></geom>
		</body>
		<body name="moveable-box10" pos="0.25 0.25 0.25">
			<joint type="free" name="moveable-box10_free" damping="0.01" pos="0 0 0"></joint>
			<geom size="0.25 0.25 0.25" type="box" condim="3" name="moveable-box10" rgba="1 0.5 0.8 1" mass="1" friction="0.2"></geom>
		</body>
		<body name="moveable-box11" pos="0.25 0.25 0.25">
			<joint type="free" name="moveable-box11_free" damping="0.01" pos="0 0 0"></joint>
			<geom size="0.25 0.25 0.25" type="box" condim="3" name="moveable-box11" rgba="1 0.5 0.8 1" mass="1" friction="0.2"></geom>
		</body>
		<body name="moveable-box12" pos="0.25 0.25 0.25">
			<joint type="free" name="moveable-box12_free" damping="0.01" pos="0 0 0"></joint>
			<geom size="0.25 0.25 0.25" type="box" condim="3" name="moveable-box12" rgba="1 0.5 0.8 1" mass="1" friction="0.2"></geom>
		</body>
		<body name="moveable-box13" pos="0.25 0.25 0.25">
			<joint type="free" name="moveable-box13_free" damping="0.01" pos="0 0 0"></joint>
			<geom size="0.25 0.25 0.25" type="box" condim="3" name="moveable-box13" rgba="1 0.5 0.8 1" mass="1" friction="0.2"></geom>
		</body>
		<body name="moveable-box14" pos="0.25 0.25 0.25">
			<joint type="free" name="moveable-box14_free" damping="0.01" pos="0 0 0"></joint>
			<geom size="0.25 0.25 0.25" type="box" condim="3" name="moveable-box14" rgba="1 0.5 0.8 1" mass="1" friction="0.2"></geom>
		</body>
		<body name="moveable-box15" pos="0.25 0.25 0.25">
			<joint type="free" name="moveable-box15_free" damping="0.01" pos="0 0 0"></joint>
			<geom size="0.25 0.25 0.25" type="box" condim="3" name="moveable-box15" rgba="1 0.5 0.8 1" mass="1" friction="0.2"></geom>
		</body>
		<body name="moveable-box16" pos="0.25 0.25 0.25">
			<joint type="free" name="moveable-box16_free" damping="0.01" pos="0 0 0"></joint>
			<geom size="0.25 0.25 0.25" type="box" condim="3" name="moveable-box16" rgba="1 0.5 0.8 1" mass="1" friction="0.2"></geom>
		</body>
		<body name="moveable-box17" pos="0.25 0.25 0.25">
			<joint type="free" name="moveable-box17_free" damping="0.01" pos="0 0 0"></joint>
			<geom size="0.25 0.25 0.25" type="box" condim="3" name="moveable-box17" rgba="1 0.5 0.8 1" mass="1" friction="0.2"></geom>
		</body>
		<body name="moveable-box18" pos="0.25 0.25 0.25">
			<joint type="free" name="moveable-box18_free" damping="0.01" pos="0 0 0"></joint>
			<geom size="0.25 0.25 0.25" type="box" condim="3" name="moveable-box18" rgba="1 0.5 0.8 1" mass="1" friction="0.2"></geom>
		</body>
	</worldbody>
	<actuator>
		<motor gear="100" joint="agent0_slide0"></motor>
		<motor gear="100" joint="agent0_slide1"></motor>
		<motor gear="100" joint="agent0_hinge0"></motor>
		<motor gear="100" joint="agent1_slide0"></motor>
		<motor gear="100" joint="agent1_slide1"></motor>
		<motor gear="100" joint="agent1_hinge0"></motor>
		<motor gear="100" joint="agent2_slide0"></motor>
		<motor gear="100" joint="agent2_slide1"></motor>
		<motor gear="100" joint="agent2_hinge0"></motor>
		<motor gear="100" joint="agent3_slide0"></motor>
		<motor gear="100" joint="agent3_slide1"></motor>
		<motor gear="100" joint="agent3_hinge0"></motor>
	</actuator>
</mujoco>