<?xml version="1.0" encoding="utf-8"?>
<mujoco>
	<compiler angle="radian" coordinate="local" meshdir="/rds/general/user/tla19/home/FYP/MAax/assets/stls" texturedir="/rds/general/user/tla19/home/FYP/MAax/assets/textures" autolimits="true"></compiler>
	<option timestep="0.005">
		<flag warmstart="enable"></flag>
	</option>
	<worldbody>
		<geom name="floor0" pos="3 3 0" size="3 3 1" type="plane" condim="3"></geom>
		<body name="floor0" pos="3 3 0"></body>
		<body name="wall0" pos="0.05 2.85 1.5">
			<joint name="wall0_slide0" axis="1 0 0" type="slide" damping="0.01" pos="0 0 0" limited="auto" range="-1.0 1.0"></joint>
			<joint name="wall0_slide1" axis="0 1 0" type="slide" damping="0.01" pos="0 0 0" limited="auto" range="-1.0 1.0"></joint>
			<geom size="0.05 2.85 1.5" type="box" condim="3" name="wall0" rgba="0.6 1 0.6 1" group="1" mass="10" friction="0.01"></geom>
		</body>
		<body name="wall1" pos="2.85 0.05 1.5">
			<joint name="wall1_slide0" axis="1 0 0" type="slide" damping="0.01" pos="0 0 0" limited="auto" range="-1.0 1.0"></joint>
			<joint name="wall1_slide1" axis="0 1 0" type="slide" damping="0.01" pos="0 0 0" limited="auto" range="-1.0 1.0"></joint>
			<geom size="2.85 0.05 1.5" type="box" condim="3" name="wall1" rgba="0.6 1 0.6 1" group="1" mass="10" friction="0.01"></geom>
		</body>
		<body name="wall2" pos="0.05 2.85 1.5">
			<joint name="wall2_slide0" axis="1 0 0" type="slide" damping="0.01" pos="0 0 0" limited="auto" range="-1.0 1.0"></joint>
			<joint name="wall2_slide1" axis="0 1 0" type="slide" damping="0.01" pos="0 0 0" limited="auto" range="-1.0 1.0"></joint>
			<geom size="0.05 2.85 1.5" type="box" condim="3" name="wall2" rgba="0.6 1 0.6 1" group="1" mass="10" friction="0.01"></geom>
		</body>
		<body name="wall3" pos="2.85 0.05 1.5">
			<joint name="wall3_slide0" axis="1 0 0" type="slide" damping="0.01" pos="0 0 0" limited="auto" range="-1.0 1.0"></joint>
			<joint name="wall3_slide1" axis="0 1 0" type="slide" damping="0.01" pos="0 0 0" limited="auto" range="-1.0 1.0"></joint>
			<geom size="2.85 0.05 1.5" type="box" condim="3" name="wall3" rgba="0.6 1 0.6 1" group="1" mass="10" friction="0.01"></geom>
		</body>
		<body name="wall4" pos="0.05 0.85 0.25">
			<joint name="wall4_slide0" axis="1 0 0" type="slide" damping="0.01" pos="0 0 0" limited="auto" range="-1.0 1.0"></joint>
			<joint name="wall4_slide1" axis="0 1 0" type="slide" damping="0.01" pos="0 0 0" limited="auto" range="-1.0 1.0"></joint>
			<geom size="0.05 0.85 0.25" type="box" condim="3" name="wall4" rgba="0.6 1 0.6 1" group="1" mass="10" friction="0.01"></geom>
		</body>
		<body name="wall5" pos="0.05 0.25 0.25">
			<joint name="wall5_slide0" axis="1 0 0" type="slide" damping="0.01" pos="0 0 0" limited="auto" range="-1.0 1.0"></joint>
			<joint name="wall5_slide1" axis="0 1 0" type="slide" damping="0.01" pos="0 0 0" limited="auto" range="-1.0 1.0"></joint>
			<geom size="0.05 0.25 0.25" type="box" condim="3" name="wall5" rgba="0.6 1 0.6 1" group="1" mass="10" friction="0.01"></geom>
		</body>
		<body name="wall6" pos="0.55 0.05 0.25">
			<joint name="wall6_slide0" axis="1 0 0" type="slide" damping="0.01" pos="0 0 0" limited="auto" range="-1.0 1.0"></joint>
			<joint name="wall6_slide1" axis="0 1 0" type="slide" damping="0.01" pos="0 0 0" limited="auto" range="-1.0 1.0"></joint>
			<geom size="0.55 0.05 0.25" type="box" condim="3" name="wall6" rgba="0.6 1 0.6 1" group="1" mass="10" friction="0.01"></geom>
		</body>
		<body name="wall7" pos="0.45 0.05 0.25">
			<joint name="wall7_slide0" axis="1 0 0" type="slide" damping="0.01" pos="0 0 0" limited="auto" range="-1.0 1.0"></joint>
			<joint name="wall7_slide1" axis="0 1 0" type="slide" damping="0.01" pos="0 0 0" limited="auto" range="-1.0 1.0"></joint>
			<geom size="0.45 0.05 0.25" type="box" condim="3" name="wall7" rgba="0.6 1 0.6 1" group="1" mass="10" friction="0.01"></geom>
		</body>
		<body pos="0.15 0.15 0.15" name="agent0_agent0">
			<joint axis="1 0 0" damping="0.01" name="agent0_slide0" pos="0 0 0" type="slide" limited="auto" range="-100 100"></joint>
			<joint axis="0 1 0" damping="0.01" name="agent0_slide1" pos="0 0 0" type="slide" limited="auto" range="-100 100"></joint>
			<joint axis="0 0 1" damping="0.01" name="agent0_hinge0" pos="0 0 0" type="hinge" limited="auto" range="-100 100"></joint>
			<geom name="agent0_agent" mass="1" pos="0 0 0" rgba="0.258824 0.921569 0.956863 1" size="0.15" type="sphere" euler="1.57 0 0" friction="0.01"></geom>
		</body>
		<body pos="0.15 0.15 0.15" name="agent1_agent1">
			<joint axis="1 0 0" damping="0.01" name="agent1_slide0" pos="0 0 0" type="slide" limited="auto" range="-100 100"></joint>
			<joint axis="0 1 0" damping="0.01" name="agent1_slide1" pos="0 0 0" type="slide" limited="auto" range="-100 100"></joint>
			<joint axis="0 0 1" damping="0.01" name="agent1_hinge0" pos="0 0 0" type="hinge" limited="auto" range="-100 100"></joint>
			<geom name="agent1_agent" mass="1" pos="0 0 0" rgba="0.258824 0.921569 0.956863 1" size="0.15" type="sphere" euler="1.57 0 0" friction="0.01"></geom>
		</body>
		<body name="moveable-box0" pos="0.25 0.25 0.25">
			<joint name="moveable-box0_slide0" axis="1 0 0" type="slide" damping="0.01" pos="0 0 0" limited="auto"></joint>
			<joint name="moveable-box0_slide1" axis="0 1 0" type="slide" damping="0.01" pos="0 0 0" limited="auto"></joint>
			<joint name="moveable-box0_slide2" axis="0 0 1" type="slide" damping="0.01" pos="0 0 0" limited="auto"></joint>
			<geom size="0.25 0.25 0.25" type="box" condim="3" name="moveable-box0" rgba="1 0.5 0.8 1" mass="1" friction="0.2"></geom>
		</body>
		<body name="moveable-box1" pos="0.25 0.25 0.25">
			<joint name="moveable-box1_slide0" axis="1 0 0" type="slide" damping="0.01" pos="0 0 0" limited="auto"></joint>
			<joint name="moveable-box1_slide1" axis="0 1 0" type="slide" damping="0.01" pos="0 0 0" limited="auto"></joint>
			<joint name="moveable-box1_slide2" axis="0 0 1" type="slide" damping="0.01" pos="0 0 0" limited="auto"></joint>
			<geom size="0.25 0.25 0.25" type="box" condim="3" name="moveable-box1" rgba="1 0.5 0.8 1" mass="1" friction="0.2"></geom>
		</body>
		<body name="moveable-box2" pos="0.25 0.25 0.25">
			<joint name="moveable-box2_slide0" axis="1 0 0" type="slide" damping="0.01" pos="0 0 0" limited="auto"></joint>
			<joint name="moveable-box2_slide1" axis="0 1 0" type="slide" damping="0.01" pos="0 0 0" limited="auto"></joint>
			<joint name="moveable-box2_slide2" axis="0 0 1" type="slide" damping="0.01" pos="0 0 0" limited="auto"></joint>
			<geom size="0.25 0.25 0.25" type="box" condim="3" name="moveable-box2" rgba="1 0.5 0.8 1" mass="1" friction="0.2"></geom>
		</body>
		<body name="moveable-box3" pos="0.25 0.25 0.25">
			<joint name="moveable-box3_slide0" axis="1 0 0" type="slide" damping="0.01" pos="0 0 0" limited="auto"></joint>
			<joint name="moveable-box3_slide1" axis="0 1 0" type="slide" damping="0.01" pos="0 0 0" limited="auto"></joint>
			<joint name="moveable-box3_slide2" axis="0 0 1" type="slide" damping="0.01" pos="0 0 0" limited="auto"></joint>
			<geom size="0.25 0.25 0.25" type="box" condim="3" name="moveable-box3" rgba="1 0.5 0.8 1" mass="1" friction="0.2"></geom>
		</body>
		<body name="moveable-box4" pos="0.25 0.25 0.25">
			<joint name="moveable-box4_slide0" axis="1 0 0" type="slide" damping="0.01" pos="0 0 0" limited="auto"></joint>
			<joint name="moveable-box4_slide1" axis="0 1 0" type="slide" damping="0.01" pos="0 0 0" limited="auto"></joint>
			<joint name="moveable-box4_slide2" axis="0 0 1" type="slide" damping="0.01" pos="0 0 0" limited="auto"></joint>
			<geom size="0.25 0.25 0.25" type="box" condim="3" name="moveable-box4" rgba="1 0.5 0.8 1" mass="1" friction="0.2"></geom>
		</body>
		<body name="moveable-box5" pos="0.25 0.25 0.25">
			<joint name="moveable-box5_slide0" axis="1 0 0" type="slide" damping="0.01" pos="0 0 0" limited="auto"></joint>
			<joint name="moveable-box5_slide1" axis="0 1 0" type="slide" damping="0.01" pos="0 0 0" limited="auto"></joint>
			<joint name="moveable-box5_slide2" axis="0 0 1" type="slide" damping="0.01" pos="0 0 0" limited="auto"></joint>
			<geom size="0.25 0.25 0.25" type="box" condim="3" name="moveable-box5" rgba="1 0.5 0.8 1" mass="1" friction="0.2"></geom>
		</body>
		<body name="moveable-box6" pos="0.25 0.25 0.25">
			<joint name="moveable-box6_slide0" axis="1 0 0" type="slide" damping="0.01" pos="0 0 0" limited="auto"></joint>
			<joint name="moveable-box6_slide1" axis="0 1 0" type="slide" damping="0.01" pos="0 0 0" limited="auto"></joint>
			<joint name="moveable-box6_slide2" axis="0 0 1" type="slide" damping="0.01" pos="0 0 0" limited="auto"></joint>
			<geom size="0.25 0.25 0.25" type="box" condim="3" name="moveable-box6" rgba="1 0.5 0.8 1" mass="1" friction="0.2"></geom>
		</body>
		<body name="moveable-box7" pos="0.25 0.25 0.25">
			<joint name="moveable-box7_slide0" axis="1 0 0" type="slide" damping="0.01" pos="0 0 0" limited="auto"></joint>
			<joint name="moveable-box7_slide1" axis="0 1 0" type="slide" damping="0.01" pos="0 0 0" limited="auto"></joint>
			<joint name="moveable-box7_slide2" axis="0 0 1" type="slide" damping="0.01" pos="0 0 0" limited="auto"></joint>
			<geom size="0.25 0.25 0.25" type="box" condim="3" name="moveable-box7" rgba="1 0.5 0.8 1" mass="1" friction="0.2"></geom>
		</body>
		<body name="moveable-box8" pos="0.25 0.25 0.25">
			<joint name="moveable-box8_slide0" axis="1 0 0" type="slide" damping="0.01" pos="0 0 0" limited="auto"></joint>
			<joint name="moveable-box8_slide1" axis="0 1 0" type="slide" damping="0.01" pos="0 0 0" limited="auto"></joint>
			<joint name="moveable-box8_slide2" axis="0 0 1" type="slide" damping="0.01" pos="0 0 0" limited="auto"></joint>
			<geom size="0.25 0.25 0.25" type="box" condim="3" name="moveable-box8" rgba="1 0.5 0.8 1" mass="1" friction="0.2"></geom>
		</body>
	</worldbody>
	<actuator>
		<motor gear="100" joint="agent0_slide0"></motor>
		<motor gear="100" joint="agent0_slide1"></motor>
		<motor gear="100" joint="agent0_hinge0"></motor>
		<motor gear="100" joint="agent1_slide0"></motor>
		<motor gear="100" joint="agent1_slide1"></motor>
		<motor gear="100" joint="agent1_hinge0"></motor>
	</actuator>
</mujoco>